[2015-03-31 19:03:08 +0000] [3493] [INFO] Starting gunicorn 19.3.0
[2015-03-31 19:03:08 +0000] [3493] [INFO] Listening at: http://127.0.0.1:8000 (3493)
[2015-03-31 19:03:08 +0000] [3493] [INFO] Using worker: sync
[2015-03-31 19:03:08 +0000] [3498] [INFO] Booting worker with pid: 3498
[2015-03-31 19:03:08 +0000] [3498] [ERROR] Exception in worker process:
Traceback (most recent call last):
  File "/home/cheeze/cheez/local/lib/python2.7/site-packages/gunicorn/arbiter.py", line 507, in spawn_worker
    worker.init_process()
  File "/home/cheeze/cheez/local/lib/python2.7/site-packages/gunicorn/workers/base.py", line 118, in init_process
    self.wsgi = self.app.wsgi()
  File "/home/cheeze/cheez/local/lib/python2.7/site-packages/gunicorn/app/base.py", line 67, in wsgi
    self.callable = self.load()
  File "/home/cheeze/cheez/local/lib/python2.7/site-packages/gunicorn/app/wsgiapp.py", line 65, in load
    return self.load_wsgiapp()
  File "/home/cheeze/cheez/local/lib/python2.7/site-packages/gunicorn/app/wsgiapp.py", line 52, in load_wsgiapp
    return util.import_app(self.app_uri)
  File "/home/cheeze/cheez/local/lib/python2.7/site-packages/gunicorn/util.py", line 355, in import_app
    __import__(module)
ImportError: No module named manage
Traceback (most recent call last):
  File "/home/cheeze/cheez/local/lib/python2.7/site-packages/gunicorn/arbiter.py", line 507, in spawn_worker
    worker.init_process()
  File "/home/cheeze/cheez/local/lib/python2.7/site-packages/gunicorn/workers/base.py", line 118, in init_process
    self.wsgi = self.app.wsgi()
  File "/home/cheeze/cheez/local/lib/python2.7/site-packages/gunicorn/app/base.py", line 67, in wsgi
    self.callable = self.load()
  File "/home/cheeze/cheez/local/lib/python2.7/site-packages/gunicorn/app/wsgiapp.py", line 65, in load
    return self.load_wsgiapp()
  File "/home/cheeze/cheez/local/lib/python2.7/site-packages/gunicorn/app/wsgiapp.py", line 52, in load_wsgiapp
    return util.import_app(self.app_uri)
  File "/home/cheeze/cheez/local/lib/python2.7/site-packages/gunicorn/util.py", line 355, in import_app
    __import__(module)
ImportError: No module named manage
[2015-03-31 19:03:08 +0000] [3498] [INFO] Worker exiting (pid: 3498)
Traceback (most recent call last):
  File "/home/cheeze/cheez/bin/gunicorn", line 11, in <module>
    sys.exit(run())
  File "/home/cheeze/cheez/local/lib/python2.7/site-packages/gunicorn/app/wsgiapp.py", line 74, in run
    WSGIApplication("%(prog)s [OPTIONS] [APP_MODULE]").run()
  File "/home/cheeze/cheez/local/lib/python2.7/site-packages/gunicorn/app/base.py", line 189, in run
    super(Application, self).run()
  File "/home/cheeze/cheez/local/lib/python2.7/site-packages/gunicorn/app/base.py", line 72, in run
    Arbiter(self).run()
  File "/home/cheeze/cheez/local/lib/python2.7/site-packages/gunicorn/arbiter.py", line 174, in run
    self.manage_workers()
  File "/home/cheeze/cheez/local/lib/python2.7/site-packages/gunicorn/arbiter.py", line 477, in manage_workers
    self.spawn_workers()
  File "/home/cheeze/cheez/local/lib/python2.7/site-packages/gunicorn/arbiter.py", line 541, in spawn_workers
    time.sleep(0.1 * random.random())
  File "/home/cheeze/cheez/local/lib/python2.7/site-packages/gunicorn/arbiter.py", line 214, in handle_chld
    self.reap_workers()
  File "/home/cheeze/cheez/local/lib/python2.7/site-packages/gunicorn/arbiter.py", line 459, in reap_workers
    raise HaltServer(reason, self.WORKER_BOOT_ERROR)
gunicorn.errors.HaltServer: <HaltServer 'Worker failed to boot.' 3>
[2015-03-31 19:03:29 +0000] [3531] [INFO] Starting gunicorn 19.3.0
[2015-03-31 19:03:29 +0000] [3531] [INFO] Listening at: http://127.0.0.1:8000 (3531)
[2015-03-31 19:03:29 +0000] [3531] [INFO] Using worker: sync
[2015-03-31 19:03:29 +0000] [3536] [INFO] Booting worker with pid: 3536
[2015-03-31 19:03:29 +0000] [3536] [ERROR] Exception in worker process:
Traceback (most recent call last):
  File "/home/cheeze/cheez/local/lib/python2.7/site-packages/gunicorn/arbiter.py", line 507, in spawn_worker
    worker.init_process()
  File "/home/cheeze/cheez/local/lib/python2.7/site-packages/gunicorn/workers/base.py", line 118, in init_process
    self.wsgi = self.app.wsgi()
  File "/home/cheeze/cheez/local/lib/python2.7/site-packages/gunicorn/app/base.py", line 67, in wsgi
    self.callable = self.load()
  File "/home/cheeze/cheez/local/lib/python2.7/site-packages/gunicorn/app/wsgiapp.py", line 65, in load
    return self.load_wsgiapp()
  File "/home/cheeze/cheez/local/lib/python2.7/site-packages/gunicorn/app/wsgiapp.py", line 52, in load_wsgiapp
    return util.import_app(self.app_uri)
  File "/home/cheeze/cheez/local/lib/python2.7/site-packages/gunicorn/util.py", line 355, in import_app
    __import__(module)
ImportError: No module named manage
Traceback (most recent call last):
  File "/home/cheeze/cheez/local/lib/python2.7/site-packages/gunicorn/arbiter.py", line 507, in spawn_worker
    worker.init_process()
  File "/home/cheeze/cheez/local/lib/python2.7/site-packages/gunicorn/workers/base.py", line 118, in init_process
    self.wsgi = self.app.wsgi()
  File "/home/cheeze/cheez/local/lib/python2.7/site-packages/gunicorn/app/base.py", line 67, in wsgi
    self.callable = self.load()
  File "/home/cheeze/cheez/local/lib/python2.7/site-packages/gunicorn/app/wsgiapp.py", line 65, in load
    return self.load_wsgiapp()
  File "/home/cheeze/cheez/local/lib/python2.7/site-packages/gunicorn/app/wsgiapp.py", line 52, in load_wsgiapp
    return util.import_app(self.app_uri)
  File "/home/cheeze/cheez/local/lib/python2.7/site-packages/gunicorn/util.py", line 355, in import_app
    __import__(module)
ImportError: No module named manage
[2015-03-31 19:03:29 +0000] [3536] [INFO] Worker exiting (pid: 3536)
Traceback (most recent call last):
  File "/home/cheeze/cheez/bin/gunicorn", line 11, in <module>
    sys.exit(run())
  File "/home/cheeze/cheez/local/lib/python2.7/site-packages/gunicorn/app/wsgiapp.py", line 74, in run
    WSGIApplication("%(prog)s [OPTIONS] [APP_MODULE]").run()
  File "/home/cheeze/cheez/local/lib/python2.7/site-packages/gunicorn/app/base.py", line 189, in run
    super(Application, self).run()
  File "/home/cheeze/cheez/local/lib/python2.7/site-packages/gunicorn/app/base.py", line 72, in run
    Arbiter(self).run()
  File "/home/cheeze/cheez/local/lib/python2.7/site-packages/gunicorn/arbiter.py", line 174, in run
    self.manage_workers()
  File "/home/cheeze/cheez/local/lib/python2.7/site-packages/gunicorn/arbiter.py", line 477, in manage_workers
    self.spawn_workers()
  File "/home/cheeze/cheez/local/lib/python2.7/site-packages/gunicorn/arbiter.py", line 541, in spawn_workers
    time.sleep(0.1 * random.random())
  File "/home/cheeze/cheez/local/lib/python2.7/site-packages/gunicorn/arbiter.py", line 214, in handle_chld
    self.reap_workers()
  File "/home/cheeze/cheez/local/lib/python2.7/site-packages/gunicorn/arbiter.py", line 459, in reap_workers
    raise HaltServer(reason, self.WORKER_BOOT_ERROR)
gunicorn.errors.HaltServer: <HaltServer 'Worker failed to boot.' 3>
