Internal Server Error: /og/
Traceback (most recent call last):
  File "/Users/jiho/Documents/workspace/django/cheez/venv/lib/python3.4/site-packages/django/core/handlers/base.py", line 132, in get_response
    response = wrapped_callback(request, *callback_args, **callback_kwargs)
  File "/Users/jiho/Documents/workspace/django/cheez/venv/lib/python3.4/site-packages/django/views/decorators/csrf.py", line 58, in wrapped_view
    return view_func(*args, **kwargs)
  File "/Users/jiho/Documents/workspace/django/cheez/venv/lib/python3.4/site-packages/rest_framework/viewsets.py", line 85, in view
    return self.dispatch(request, *args, **kwargs)
  File "/Users/jiho/Documents/workspace/django/cheez/venv/lib/python3.4/site-packages/rest_framework/views.py", line 452, in dispatch
    response = self.handle_exception(exc)
  File "/Users/jiho/Documents/workspace/django/cheez/venv/lib/python3.4/site-packages/rest_framework/views.py", line 449, in dispatch
    response = handler(request, *args, **kwargs)
  File "/Users/jiho/Documents/workspace/django/cheez/cheez/ogp/views.py", line 30, in create
    serializer.is_valid(raise_exception=True)
  File "/Users/jiho/Documents/workspace/django/cheez/venv/lib/python3.4/site-packages/rest_framework/serializers.py", line 181, in is_valid
    'Cannot call `.is_valid()` as no `data=` keyword argument was '
AssertionError: Cannot call `.is_valid()` as no `data=` keyword argument was passed when instantiating the serializer instance.
Internal Server Error: /og/
Traceback (most recent call last):
  File "/Users/jiho/Documents/workspace/django/cheez/venv/lib/python3.4/site-packages/django/core/handlers/base.py", line 132, in get_response
    response = wrapped_callback(request, *callback_args, **callback_kwargs)
  File "/Users/jiho/Documents/workspace/django/cheez/venv/lib/python3.4/site-packages/django/views/decorators/csrf.py", line 58, in wrapped_view
    return view_func(*args, **kwargs)
  File "/Users/jiho/Documents/workspace/django/cheez/venv/lib/python3.4/site-packages/rest_framework/viewsets.py", line 85, in view
    return self.dispatch(request, *args, **kwargs)
  File "/Users/jiho/Documents/workspace/django/cheez/venv/lib/python3.4/site-packages/rest_framework/views.py", line 452, in dispatch
    response = self.handle_exception(exc)
  File "/Users/jiho/Documents/workspace/django/cheez/venv/lib/python3.4/site-packages/rest_framework/views.py", line 449, in dispatch
    response = handler(request, *args, **kwargs)
  File "/Users/jiho/Documents/workspace/django/cheez/cheez/ogp/views.py", line 31, in create
    serializer.save()
  File "/Users/jiho/Documents/workspace/django/cheez/venv/lib/python3.4/site-packages/rest_framework/serializers.py", line 147, in save
    'You must call `.is_valid()` before calling `.save()`.'
AssertionError: You must call `.is_valid()` before calling `.save()`.
Internal Server Error: /post/
Traceback (most recent call last):
  File "/Users/jiho/Documents/workspace/django/cheez/venv/lib/python3.4/site-packages/django/core/handlers/base.py", line 132, in get_response
    response = wrapped_callback(request, *callback_args, **callback_kwargs)
  File "/Users/jiho/Documents/workspace/django/cheez/venv/lib/python3.4/site-packages/django/views/decorators/csrf.py", line 58, in wrapped_view
    return view_func(*args, **kwargs)
  File "/Users/jiho/Documents/workspace/django/cheez/venv/lib/python3.4/site-packages/rest_framework/viewsets.py", line 85, in view
    return self.dispatch(request, *args, **kwargs)
  File "/Users/jiho/Documents/workspace/django/cheez/venv/lib/python3.4/site-packages/rest_framework/views.py", line 452, in dispatch
    response = self.handle_exception(exc)
  File "/Users/jiho/Documents/workspace/django/cheez/venv/lib/python3.4/site-packages/rest_framework/views.py", line 449, in dispatch
    response = handler(request, *args, **kwargs)
  File "/Users/jiho/Documents/workspace/django/cheez/cheez/posts/views.py", line 33, in create
    serializer.is_valid(raise_exception=True)
  File "/Users/jiho/Documents/workspace/django/cheez/venv/lib/python3.4/site-packages/rest_framework/serializers.py", line 187, in is_valid
    self._validated_data = self.run_validation(self.initial_data)
  File "/Users/jiho/Documents/workspace/django/cheez/venv/lib/python3.4/site-packages/rest_framework/serializers.py", line 367, in run_validation
    value = self.to_internal_value(data)
  File "/Users/jiho/Documents/workspace/django/cheez/venv/lib/python3.4/site-packages/rest_framework/serializers.py", line 392, in to_internal_value
    field for field in self.fields.values()
  File "/Users/jiho/Documents/workspace/django/cheez/venv/lib/python3.4/site-packages/rest_framework/serializers.py", line 313, in fields
    for key, value in self.get_fields().items():
  File "/Users/jiho/Documents/workspace/django/cheez/venv/lib/python3.4/site-packages/rest_framework/serializers.py", line 857, in get_fields
    field_name, info, model, depth
  File "/Users/jiho/Documents/workspace/django/cheez/venv/lib/python3.4/site-packages/rest_framework/serializers.py", line 980, in build_field
    return self.build_unknown_field(field_name, model_class)
  File "/Users/jiho/Documents/workspace/django/cheez/venv/lib/python3.4/site-packages/rest_framework/serializers.py", line 1068, in build_unknown_field
    (field_name, model_class.__name__)
django.core.exceptions.ImproperlyConfigured: Field name `rated` is not valid for model `Post`.
Internal Server Error: /user/
Traceback (most recent call last):
  File "/Users/jiho/Documents/workspace/django/cheez/venv/lib/python3.4/site-packages/django/core/urlresolvers.py", line 394, in urlconf_module
    return self._urlconf_module
AttributeError: 'RegexURLResolver' object has no attribute '_urlconf_module'

During handling of the above exception, another exception occurred:

Traceback (most recent call last):
  File "/Users/jiho/Documents/workspace/django/cheez/venv/lib/python3.4/site-packages/django/core/handlers/base.py", line 119, in get_response
    resolver_match = resolver.resolve(request.path_info)
  File "/Users/jiho/Documents/workspace/django/cheez/venv/lib/python3.4/site-packages/django/core/urlresolvers.py", line 366, in resolve
    for pattern in self.url_patterns:
  File "/Users/jiho/Documents/workspace/django/cheez/venv/lib/python3.4/site-packages/django/core/urlresolvers.py", line 402, in url_patterns
    patterns = getattr(self.urlconf_module, "urlpatterns", self.urlconf_module)
  File "/Users/jiho/Documents/workspace/django/cheez/venv/lib/python3.4/site-packages/django/core/urlresolvers.py", line 396, in urlconf_module
    self._urlconf_module = import_module(self.urlconf_name)
  File "/Users/jiho/Documents/workspace/django/cheez/venv/lib/python3.4/importlib/__init__.py", line 109, in import_module
    return _bootstrap._gcd_import(name[level:], package, level)
  File "<frozen importlib._bootstrap>", line 2254, in _gcd_import
  File "<frozen importlib._bootstrap>", line 2237, in _find_and_load
  File "<frozen importlib._bootstrap>", line 2226, in _find_and_load_unlocked
  File "<frozen importlib._bootstrap>", line 1200, in _load_unlocked
  File "<frozen importlib._bootstrap>", line 1129, in _exec
  File "<frozen importlib._bootstrap>", line 1471, in exec_module
  File "<frozen importlib._bootstrap>", line 321, in _call_with_frames_removed
  File "/Users/jiho/Documents/workspace/django/cheez/cheez/cheez/urls.py", line 5, in <module>
    from posts import views as post_views
  File "/Users/jiho/Documents/workspace/django/cheez/cheez/posts/views.py", line 10, in <module>
    from posts.serializers import PostSerializer
  File "/Users/jiho/Documents/workspace/django/cheez/cheez/posts/serializers.py", line 7, in <module>
    class PostSerializer(ModelSerializer):
  File "/Users/jiho/Documents/workspace/django/cheez/cheez/posts/serializers.py", line 9, in PostSerializer
    readpostrel = ReadPostRelSerializer(many=False, read_only=True)
NameError: name 'ReadPostRelSerializer' is not defined
Internal Server Error: /post/
Traceback (most recent call last):
  File "/Users/jiho/Documents/workspace/django/cheez/venv/lib/python3.4/site-packages/django/core/handlers/base.py", line 132, in get_response
    response = wrapped_callback(request, *callback_args, **callback_kwargs)
  File "/Users/jiho/Documents/workspace/django/cheez/venv/lib/python3.4/site-packages/django/views/decorators/csrf.py", line 58, in wrapped_view
    return view_func(*args, **kwargs)
  File "/Users/jiho/Documents/workspace/django/cheez/venv/lib/python3.4/site-packages/rest_framework/viewsets.py", line 85, in view
    return self.dispatch(request, *args, **kwargs)
  File "/Users/jiho/Documents/workspace/django/cheez/venv/lib/python3.4/site-packages/rest_framework/views.py", line 452, in dispatch
    response = self.handle_exception(exc)
  File "/Users/jiho/Documents/workspace/django/cheez/venv/lib/python3.4/site-packages/rest_framework/views.py", line 449, in dispatch
    response = handler(request, *args, **kwargs)
  File "/Users/jiho/Documents/workspace/django/cheez/cheez/posts/views.py", line 33, in create
    serializer.is_valid(raise_exception=True)
  File "/Users/jiho/Documents/workspace/django/cheez/venv/lib/python3.4/site-packages/rest_framework/serializers.py", line 187, in is_valid
    self._validated_data = self.run_validation(self.initial_data)
  File "/Users/jiho/Documents/workspace/django/cheez/venv/lib/python3.4/site-packages/rest_framework/serializers.py", line 367, in run_validation
    value = self.to_internal_value(data)
  File "/Users/jiho/Documents/workspace/django/cheez/venv/lib/python3.4/site-packages/rest_framework/serializers.py", line 392, in to_internal_value
    field for field in self.fields.values()
  File "/Users/jiho/Documents/workspace/django/cheez/venv/lib/python3.4/site-packages/rest_framework/serializers.py", line 313, in fields
    for key, value in self.get_fields().items():
  File "/Users/jiho/Documents/workspace/django/cheez/venv/lib/python3.4/site-packages/rest_framework/serializers.py", line 837, in get_fields
    field_names = self.get_field_names(declared_fields, info)
  File "/Users/jiho/Documents/workspace/django/cheez/venv/lib/python3.4/site-packages/rest_framework/serializers.py", line 922, in get_field_names
    serializer_class=self.__class__.__name__
AssertionError: The field 'read_post_rels' was declared on serializer PostSerializer, but has not been included in the 'fields' option.
Internal Server Error: /post/
Traceback (most recent call last):
  File "/Users/jiho/Documents/workspace/django/cheez/venv/lib/python3.4/site-packages/django/core/handlers/base.py", line 132, in get_response
    response = wrapped_callback(request, *callback_args, **callback_kwargs)
  File "/Users/jiho/Documents/workspace/django/cheez/venv/lib/python3.4/site-packages/django/views/decorators/csrf.py", line 58, in wrapped_view
    return view_func(*args, **kwargs)
  File "/Users/jiho/Documents/workspace/django/cheez/venv/lib/python3.4/site-packages/rest_framework/viewsets.py", line 85, in view
    return self.dispatch(request, *args, **kwargs)
  File "/Users/jiho/Documents/workspace/django/cheez/venv/lib/python3.4/site-packages/rest_framework/views.py", line 452, in dispatch
    response = self.handle_exception(exc)
  File "/Users/jiho/Documents/workspace/django/cheez/venv/lib/python3.4/site-packages/rest_framework/views.py", line 449, in dispatch
    response = handler(request, *args, **kwargs)
  File "/Users/jiho/Documents/workspace/django/cheez/cheez/posts/views.py", line 36, in create
    return Response(serializer.data, status.HTTP_201_CREATED)
  File "/Users/jiho/Documents/workspace/django/cheez/venv/lib/python3.4/site-packages/rest_framework/serializers.py", line 466, in data
    ret = super(Serializer, self).data
  File "/Users/jiho/Documents/workspace/django/cheez/venv/lib/python3.4/site-packages/rest_framework/serializers.py", line 213, in data
    self._data = self.to_representation(self.instance)
  File "/Users/jiho/Documents/workspace/django/cheez/venv/lib/python3.4/site-packages/rest_framework/serializers.py", line 435, in to_representation
    ret[field.field_name] = field.to_representation(attribute)
  File "/Users/jiho/Documents/workspace/django/cheez/venv/lib/python3.4/site-packages/rest_framework/serializers.py", line 426, in to_representation
    attribute = field.get_attribute(instance)
  File "/Users/jiho/Documents/workspace/django/cheez/venv/lib/python3.4/site-packages/rest_framework/relations.py", line 103, in get_attribute
    return get_attribute(instance, self.source_attrs)
  File "/Users/jiho/Documents/workspace/django/cheez/venv/lib/python3.4/site-packages/rest_framework/fields.py", line 70, in get_attribute
    instance = getattr(instance, attr)
AttributeError: 'RelatedManager' object has no attribute 'user'
Internal Server Error: /post/
Traceback (most recent call last):
  File "/Users/jiho/Documents/workspace/django/cheez/venv/lib/python3.4/site-packages/django/core/handlers/base.py", line 132, in get_response
    response = wrapped_callback(request, *callback_args, **callback_kwargs)
  File "/Users/jiho/Documents/workspace/django/cheez/venv/lib/python3.4/site-packages/django/views/decorators/csrf.py", line 58, in wrapped_view
    return view_func(*args, **kwargs)
  File "/Users/jiho/Documents/workspace/django/cheez/venv/lib/python3.4/site-packages/rest_framework/viewsets.py", line 85, in view
    return self.dispatch(request, *args, **kwargs)
  File "/Users/jiho/Documents/workspace/django/cheez/venv/lib/python3.4/site-packages/rest_framework/views.py", line 452, in dispatch
    response = self.handle_exception(exc)
  File "/Users/jiho/Documents/workspace/django/cheez/venv/lib/python3.4/site-packages/rest_framework/views.py", line 449, in dispatch
    response = handler(request, *args, **kwargs)
  File "/Users/jiho/Documents/workspace/django/cheez/cheez/posts/views.py", line 36, in create
    return Response(serializer.data, status.HTTP_201_CREATED)
  File "/Users/jiho/Documents/workspace/django/cheez/venv/lib/python3.4/site-packages/rest_framework/serializers.py", line 466, in data
    ret = super(Serializer, self).data
  File "/Users/jiho/Documents/workspace/django/cheez/venv/lib/python3.4/site-packages/rest_framework/serializers.py", line 213, in data
    self._data = self.to_representation(self.instance)
  File "/Users/jiho/Documents/workspace/django/cheez/venv/lib/python3.4/site-packages/rest_framework/serializers.py", line 435, in to_representation
    ret[field.field_name] = field.to_representation(attribute)
  File "/Users/jiho/Documents/workspace/django/cheez/venv/lib/python3.4/site-packages/rest_framework/serializers.py", line 426, in to_representation
    attribute = field.get_attribute(instance)
  File "/Users/jiho/Documents/workspace/django/cheez/venv/lib/python3.4/site-packages/rest_framework/relations.py", line 103, in get_attribute
    return get_attribute(instance, self.source_attrs)
  File "/Users/jiho/Documents/workspace/django/cheez/venv/lib/python3.4/site-packages/rest_framework/fields.py", line 70, in get_attribute
    instance = getattr(instance, attr)
AttributeError: 'RelatedManager' object has no attribute 'user'
Internal Server Error: /post/
Traceback (most recent call last):
  File "/Users/jiho/Documents/workspace/django/cheez/venv/lib/python3.4/site-packages/django/core/handlers/base.py", line 132, in get_response
    response = wrapped_callback(request, *callback_args, **callback_kwargs)
  File "/Users/jiho/Documents/workspace/django/cheez/venv/lib/python3.4/site-packages/django/views/decorators/csrf.py", line 58, in wrapped_view
    return view_func(*args, **kwargs)
  File "/Users/jiho/Documents/workspace/django/cheez/venv/lib/python3.4/site-packages/rest_framework/viewsets.py", line 85, in view
    return self.dispatch(request, *args, **kwargs)
  File "/Users/jiho/Documents/workspace/django/cheez/venv/lib/python3.4/site-packages/rest_framework/views.py", line 452, in dispatch
    response = self.handle_exception(exc)
  File "/Users/jiho/Documents/workspace/django/cheez/venv/lib/python3.4/site-packages/rest_framework/views.py", line 449, in dispatch
    response = handler(request, *args, **kwargs)
  File "/Users/jiho/Documents/workspace/django/cheez/cheez/posts/views.py", line 54, in list
    return Response({'results': serializer.data})
  File "/Users/jiho/Documents/workspace/django/cheez/venv/lib/python3.4/site-packages/rest_framework/serializers.py", line 618, in data
    ret = super(ListSerializer, self).data
  File "/Users/jiho/Documents/workspace/django/cheez/venv/lib/python3.4/site-packages/rest_framework/serializers.py", line 213, in data
    self._data = self.to_representation(self.instance)
  File "/Users/jiho/Documents/workspace/django/cheez/venv/lib/python3.4/site-packages/rest_framework/serializers.py", line 568, in to_representation
    self.child.to_representation(item) for item in iterable
  File "/Users/jiho/Documents/workspace/django/cheez/venv/lib/python3.4/site-packages/rest_framework/serializers.py", line 568, in <listcomp>
    self.child.to_representation(item) for item in iterable
  File "/Users/jiho/Documents/workspace/django/cheez/cheez/posts/serializers.py", line 20, in to_representation
    representation['rating'] = representation['read_post_rels'][0].rating
AttributeError: 'OrderedDict' object has no attribute 'rating'
Internal Server Error: /post/
Traceback (most recent call last):
  File "/Users/jiho/Documents/workspace/django/cheez/venv/lib/python3.4/site-packages/django/core/handlers/base.py", line 132, in get_response
    response = wrapped_callback(request, *callback_args, **callback_kwargs)
  File "/Users/jiho/Documents/workspace/django/cheez/venv/lib/python3.4/site-packages/django/views/decorators/csrf.py", line 58, in wrapped_view
    return view_func(*args, **kwargs)
  File "/Users/jiho/Documents/workspace/django/cheez/venv/lib/python3.4/site-packages/rest_framework/viewsets.py", line 85, in view
    return self.dispatch(request, *args, **kwargs)
  File "/Users/jiho/Documents/workspace/django/cheez/venv/lib/python3.4/site-packages/rest_framework/views.py", line 452, in dispatch
    response = self.handle_exception(exc)
  File "/Users/jiho/Documents/workspace/django/cheez/venv/lib/python3.4/site-packages/rest_framework/views.py", line 449, in dispatch
    response = handler(request, *args, **kwargs)
  File "/Users/jiho/Documents/workspace/django/cheez/cheez/posts/views.py", line 54, in list
    return Response({'results': serializer.data})
  File "/Users/jiho/Documents/workspace/django/cheez/venv/lib/python3.4/site-packages/rest_framework/serializers.py", line 618, in data
    ret = super(ListSerializer, self).data
  File "/Users/jiho/Documents/workspace/django/cheez/venv/lib/python3.4/site-packages/rest_framework/serializers.py", line 213, in data
    self._data = self.to_representation(self.instance)
  File "/Users/jiho/Documents/workspace/django/cheez/venv/lib/python3.4/site-packages/rest_framework/serializers.py", line 568, in to_representation
    self.child.to_representation(item) for item in iterable
  File "/Users/jiho/Documents/workspace/django/cheez/venv/lib/python3.4/site-packages/rest_framework/serializers.py", line 568, in <listcomp>
    self.child.to_representation(item) for item in iterable
  File "/Users/jiho/Documents/workspace/django/cheez/cheez/posts/serializers.py", line 21, in to_representation
    representation['rating'] = representation['read_post_rels'][0].rating
AttributeError: 'OrderedDict' object has no attribute 'rating'
Internal Server Error: /post/
Traceback (most recent call last):
  File "/Users/jiho/Documents/workspace/django/cheez/venv/lib/python3.4/site-packages/django/core/handlers/base.py", line 132, in get_response
    response = wrapped_callback(request, *callback_args, **callback_kwargs)
  File "/Users/jiho/Documents/workspace/django/cheez/venv/lib/python3.4/site-packages/django/views/decorators/csrf.py", line 58, in wrapped_view
    return view_func(*args, **kwargs)
  File "/Users/jiho/Documents/workspace/django/cheez/venv/lib/python3.4/site-packages/rest_framework/viewsets.py", line 85, in view
    return self.dispatch(request, *args, **kwargs)
  File "/Users/jiho/Documents/workspace/django/cheez/venv/lib/python3.4/site-packages/rest_framework/views.py", line 452, in dispatch
    response = self.handle_exception(exc)
  File "/Users/jiho/Documents/workspace/django/cheez/venv/lib/python3.4/site-packages/rest_framework/views.py", line 449, in dispatch
    response = handler(request, *args, **kwargs)
  File "/Users/jiho/Documents/workspace/django/cheez/cheez/posts/views.py", line 56, in list
    return Response({'results': serializer.data})
  File "/Users/jiho/Documents/workspace/django/cheez/venv/lib/python3.4/site-packages/rest_framework/serializers.py", line 618, in data
    ret = super(ListSerializer, self).data
  File "/Users/jiho/Documents/workspace/django/cheez/venv/lib/python3.4/site-packages/rest_framework/serializers.py", line 213, in data
    self._data = self.to_representation(self.instance)
  File "/Users/jiho/Documents/workspace/django/cheez/venv/lib/python3.4/site-packages/rest_framework/serializers.py", line 568, in to_representation
    self.child.to_representation(item) for item in iterable
  File "/Users/jiho/Documents/workspace/django/cheez/venv/lib/python3.4/site-packages/rest_framework/serializers.py", line 568, in <listcomp>
    self.child.to_representation(item) for item in iterable
  File "/Users/jiho/Documents/workspace/django/cheez/cheez/posts/serializers.py", line 21, in to_representation
    representation['rating'] = representation['read_post_rels'][0].rating
AttributeError: 'OrderedDict' object has no attribute 'rating'
Internal Server Error: /post/
Traceback (most recent call last):
  File "/Users/jiho/Documents/workspace/django/cheez/venv/lib/python3.4/site-packages/django/core/handlers/base.py", line 132, in get_response
    response = wrapped_callback(request, *callback_args, **callback_kwargs)
  File "/Users/jiho/Documents/workspace/django/cheez/venv/lib/python3.4/site-packages/django/views/decorators/csrf.py", line 58, in wrapped_view
    return view_func(*args, **kwargs)
  File "/Users/jiho/Documents/workspace/django/cheez/venv/lib/python3.4/site-packages/rest_framework/viewsets.py", line 85, in view
    return self.dispatch(request, *args, **kwargs)
  File "/Users/jiho/Documents/workspace/django/cheez/venv/lib/python3.4/site-packages/rest_framework/views.py", line 452, in dispatch
    response = self.handle_exception(exc)
  File "/Users/jiho/Documents/workspace/django/cheez/venv/lib/python3.4/site-packages/rest_framework/views.py", line 449, in dispatch
    response = handler(request, *args, **kwargs)
  File "/Users/jiho/Documents/workspace/django/cheez/cheez/posts/views.py", line 57, in list
    return Response({'results': serializer.data})
  File "/Users/jiho/Documents/workspace/django/cheez/venv/lib/python3.4/site-packages/rest_framework/serializers.py", line 618, in data
    ret = super(ListSerializer, self).data
  File "/Users/jiho/Documents/workspace/django/cheez/venv/lib/python3.4/site-packages/rest_framework/serializers.py", line 213, in data
    self._data = self.to_representation(self.instance)
  File "/Users/jiho/Documents/workspace/django/cheez/venv/lib/python3.4/site-packages/rest_framework/serializers.py", line 568, in to_representation
    self.child.to_representation(item) for item in iterable
  File "/Users/jiho/Documents/workspace/django/cheez/venv/lib/python3.4/site-packages/rest_framework/serializers.py", line 568, in <listcomp>
    self.child.to_representation(item) for item in iterable
  File "/Users/jiho/Documents/workspace/django/cheez/cheez/posts/serializers.py", line 21, in to_representation
    representation['rating'] = representation['read_post_rels'][0].rating
AttributeError: 'OrderedDict' object has no attribute 'rating'
Internal Server Error: /post/
Traceback (most recent call last):
  File "/Users/jiho/Documents/workspace/django/cheez/venv/lib/python3.4/site-packages/django/core/handlers/base.py", line 132, in get_response
    response = wrapped_callback(request, *callback_args, **callback_kwargs)
  File "/Users/jiho/Documents/workspace/django/cheez/venv/lib/python3.4/site-packages/django/views/decorators/csrf.py", line 58, in wrapped_view
    return view_func(*args, **kwargs)
  File "/Users/jiho/Documents/workspace/django/cheez/venv/lib/python3.4/site-packages/rest_framework/viewsets.py", line 85, in view
    return self.dispatch(request, *args, **kwargs)
  File "/Users/jiho/Documents/workspace/django/cheez/venv/lib/python3.4/site-packages/rest_framework/views.py", line 452, in dispatch
    response = self.handle_exception(exc)
  File "/Users/jiho/Documents/workspace/django/cheez/venv/lib/python3.4/site-packages/rest_framework/views.py", line 449, in dispatch
    response = handler(request, *args, **kwargs)
  File "/Users/jiho/Documents/workspace/django/cheez/cheez/posts/views.py", line 54, in list
    return Response(serializer.data)
  File "/Users/jiho/Documents/workspace/django/cheez/venv/lib/python3.4/site-packages/rest_framework/serializers.py", line 618, in data
    ret = super(ListSerializer, self).data
  File "/Users/jiho/Documents/workspace/django/cheez/venv/lib/python3.4/site-packages/rest_framework/serializers.py", line 213, in data
    self._data = self.to_representation(self.instance)
  File "/Users/jiho/Documents/workspace/django/cheez/venv/lib/python3.4/site-packages/rest_framework/serializers.py", line 568, in to_representation
    self.child.to_representation(item) for item in iterable
  File "/Users/jiho/Documents/workspace/django/cheez/venv/lib/python3.4/site-packages/rest_framework/serializers.py", line 568, in <listcomp>
    self.child.to_representation(item) for item in iterable
  File "/Users/jiho/Documents/workspace/django/cheez/cheez/posts/serializers.py", line 21, in to_representation
    representation['rating'] = representation['read_post_rels'][0].rating
AttributeError: 'OrderedDict' object has no attribute 'rating'
Internal Server Error: /post/
Traceback (most recent call last):
  File "/Users/jiho/Documents/workspace/django/cheez/venv/lib/python3.4/site-packages/django/core/handlers/base.py", line 132, in get_response
    response = wrapped_callback(request, *callback_args, **callback_kwargs)
  File "/Users/jiho/Documents/workspace/django/cheez/venv/lib/python3.4/site-packages/django/views/decorators/csrf.py", line 58, in wrapped_view
    return view_func(*args, **kwargs)
  File "/Users/jiho/Documents/workspace/django/cheez/venv/lib/python3.4/site-packages/rest_framework/viewsets.py", line 85, in view
    return self.dispatch(request, *args, **kwargs)
  File "/Users/jiho/Documents/workspace/django/cheez/venv/lib/python3.4/site-packages/rest_framework/views.py", line 452, in dispatch
    response = self.handle_exception(exc)
  File "/Users/jiho/Documents/workspace/django/cheez/venv/lib/python3.4/site-packages/rest_framework/views.py", line 449, in dispatch
    response = handler(request, *args, **kwargs)
  File "/Users/jiho/Documents/workspace/django/cheez/cheez/posts/views.py", line 54, in list
    return Response(serializer.data)
  File "/Users/jiho/Documents/workspace/django/cheez/venv/lib/python3.4/site-packages/rest_framework/serializers.py", line 618, in data
    ret = super(ListSerializer, self).data
  File "/Users/jiho/Documents/workspace/django/cheez/venv/lib/python3.4/site-packages/rest_framework/serializers.py", line 213, in data
    self._data = self.to_representation(self.instance)
  File "/Users/jiho/Documents/workspace/django/cheez/venv/lib/python3.4/site-packages/rest_framework/serializers.py", line 568, in to_representation
    self.child.to_representation(item) for item in iterable
  File "/Users/jiho/Documents/workspace/django/cheez/venv/lib/python3.4/site-packages/rest_framework/serializers.py", line 568, in <listcomp>
    self.child.to_representation(item) for item in iterable
  File "/Users/jiho/Documents/workspace/django/cheez/cheez/posts/serializers.py", line 21, in to_representation
    representation['rating'] = representation['read_post_rels'][0].rating
AttributeError: 'OrderedDict' object has no attribute 'rating'
Internal Server Error: /post/
Traceback (most recent call last):
  File "/Users/jiho/Documents/workspace/django/cheez/venv/lib/python3.4/site-packages/django/core/handlers/base.py", line 132, in get_response
    response = wrapped_callback(request, *callback_args, **callback_kwargs)
  File "/Users/jiho/Documents/workspace/django/cheez/venv/lib/python3.4/site-packages/django/views/decorators/csrf.py", line 58, in wrapped_view
    return view_func(*args, **kwargs)
  File "/Users/jiho/Documents/workspace/django/cheez/venv/lib/python3.4/site-packages/rest_framework/viewsets.py", line 85, in view
    return self.dispatch(request, *args, **kwargs)
  File "/Users/jiho/Documents/workspace/django/cheez/venv/lib/python3.4/site-packages/rest_framework/views.py", line 452, in dispatch
    response = self.handle_exception(exc)
  File "/Users/jiho/Documents/workspace/django/cheez/venv/lib/python3.4/site-packages/rest_framework/views.py", line 449, in dispatch
    response = handler(request, *args, **kwargs)
  File "/Users/jiho/Documents/workspace/django/cheez/cheez/posts/views.py", line 51, in list
    [request.user.id, (page-1)*PostViewSet.PAGE_SIZE, PostViewSet.PAGE_SIZE]
TypeError: unsupported operand type(s) for -: 'str' and 'int'
Internal Server Error: /post/
Traceback (most recent call last):
  File "/Users/jiho/Documents/workspace/django/cheez/venv/lib/python3.4/site-packages/django/db/backends/utils.py", line 64, in execute
    return self.cursor.execute(sql, params)
  File "/Users/jiho/Documents/workspace/django/cheez/venv/lib/python3.4/site-packages/django/db/backends/sqlite3/base.py", line 318, in execute
    return Database.Cursor.execute(self, query, params)
sqlite3.OperationalError: near "?": syntax error

The above exception was the direct cause of the following exception:

Traceback (most recent call last):
  File "/Users/jiho/Documents/workspace/django/cheez/venv/lib/python3.4/site-packages/django/core/handlers/base.py", line 132, in get_response
    response = wrapped_callback(request, *callback_args, **callback_kwargs)
  File "/Users/jiho/Documents/workspace/django/cheez/venv/lib/python3.4/site-packages/django/views/decorators/csrf.py", line 58, in wrapped_view
    return view_func(*args, **kwargs)
  File "/Users/jiho/Documents/workspace/django/cheez/venv/lib/python3.4/site-packages/rest_framework/viewsets.py", line 85, in view
    return self.dispatch(request, *args, **kwargs)
  File "/Users/jiho/Documents/workspace/django/cheez/venv/lib/python3.4/site-packages/rest_framework/views.py", line 452, in dispatch
    response = self.handle_exception(exc)
  File "/Users/jiho/Documents/workspace/django/cheez/venv/lib/python3.4/site-packages/rest_framework/views.py", line 449, in dispatch
    response = handler(request, *args, **kwargs)
  File "/Users/jiho/Documents/workspace/django/cheez/cheez/posts/views.py", line 62, in list
    return Response({'results': serializer.data})
  File "/Users/jiho/Documents/workspace/django/cheez/venv/lib/python3.4/site-packages/rest_framework/serializers.py", line 618, in data
    ret = super(ListSerializer, self).data
  File "/Users/jiho/Documents/workspace/django/cheez/venv/lib/python3.4/site-packages/rest_framework/serializers.py", line 213, in data
    self._data = self.to_representation(self.instance)
  File "/Users/jiho/Documents/workspace/django/cheez/venv/lib/python3.4/site-packages/rest_framework/serializers.py", line 568, in to_representation
    self.child.to_representation(item) for item in iterable
  File "/Users/jiho/Documents/workspace/django/cheez/venv/lib/python3.4/site-packages/rest_framework/serializers.py", line 568, in <listcomp>
    self.child.to_representation(item) for item in iterable
  File "/Users/jiho/Documents/workspace/django/cheez/venv/lib/python3.4/site-packages/django/db/models/query.py", line 1284, in __iter__
    query = iter(self.query)
  File "/Users/jiho/Documents/workspace/django/cheez/venv/lib/python3.4/site-packages/django/db/models/sql/query.py", line 78, in __iter__
    self._execute_query()
  File "/Users/jiho/Documents/workspace/django/cheez/venv/lib/python3.4/site-packages/django/db/models/sql/query.py", line 96, in _execute_query
    self.cursor.execute(self.sql, self.params)
  File "/Users/jiho/Documents/workspace/django/cheez/venv/lib/python3.4/site-packages/django/db/backends/utils.py", line 64, in execute
    return self.cursor.execute(sql, params)
  File "/Users/jiho/Documents/workspace/django/cheez/venv/lib/python3.4/site-packages/django/db/utils.py", line 97, in __exit__
    six.reraise(dj_exc_type, dj_exc_value, traceback)
  File "/Users/jiho/Documents/workspace/django/cheez/venv/lib/python3.4/site-packages/django/utils/six.py", line 658, in reraise
    raise value.with_traceback(tb)
  File "/Users/jiho/Documents/workspace/django/cheez/venv/lib/python3.4/site-packages/django/db/backends/utils.py", line 64, in execute
    return self.cursor.execute(sql, params)
  File "/Users/jiho/Documents/workspace/django/cheez/venv/lib/python3.4/site-packages/django/db/backends/sqlite3/base.py", line 318, in execute
    return Database.Cursor.execute(self, query, params)
django.db.utils.OperationalError: near "?": syntax error
Internal Server Error: /read-post/
Traceback (most recent call last):
  File "/Users/jiho/Documents/workspace/django/cheez/venv/lib/python3.4/site-packages/django/core/handlers/base.py", line 132, in get_response
    response = wrapped_callback(request, *callback_args, **callback_kwargs)
  File "/Users/jiho/Documents/workspace/django/cheez/venv/lib/python3.4/site-packages/django/views/decorators/csrf.py", line 58, in wrapped_view
    return view_func(*args, **kwargs)
  File "/Users/jiho/Documents/workspace/django/cheez/venv/lib/python3.4/site-packages/django/views/generic/base.py", line 71, in view
    return self.dispatch(request, *args, **kwargs)
  File "/Users/jiho/Documents/workspace/django/cheez/venv/lib/python3.4/site-packages/rest_framework/views.py", line 452, in dispatch
    response = self.handle_exception(exc)
  File "/Users/jiho/Documents/workspace/django/cheez/venv/lib/python3.4/site-packages/rest_framework/views.py", line 449, in dispatch
    response = handler(request, *args, **kwargs)
  File "/Users/jiho/Documents/workspace/django/cheez/cheez/posts/views.py", line 125, in post
    saved = request.data['saved']
KeyError: 'saved'
Internal Server Error: /4/
Traceback (most recent call last):
  File "/Users/jiho/Documents/workspace/django/cheez/venv/lib/python3.4/site-packages/django/core/urlresolvers.py", line 394, in urlconf_module
    return self._urlconf_module
AttributeError: 'RegexURLResolver' object has no attribute '_urlconf_module'

During handling of the above exception, another exception occurred:

Traceback (most recent call last):
  File "/Users/jiho/Documents/workspace/django/cheez/venv/lib/python3.4/site-packages/django/core/handlers/base.py", line 119, in get_response
    resolver_match = resolver.resolve(request.path_info)
  File "/Users/jiho/Documents/workspace/django/cheez/venv/lib/python3.4/site-packages/django/core/urlresolvers.py", line 366, in resolve
    for pattern in self.url_patterns:
  File "/Users/jiho/Documents/workspace/django/cheez/venv/lib/python3.4/site-packages/django/core/urlresolvers.py", line 402, in url_patterns
    patterns = getattr(self.urlconf_module, "urlpatterns", self.urlconf_module)
  File "/Users/jiho/Documents/workspace/django/cheez/venv/lib/python3.4/site-packages/django/core/urlresolvers.py", line 396, in urlconf_module
    self._urlconf_module = import_module(self.urlconf_name)
  File "/Users/jiho/Documents/workspace/django/cheez/venv/lib/python3.4/importlib/__init__.py", line 109, in import_module
    return _bootstrap._gcd_import(name[level:], package, level)
  File "<frozen importlib._bootstrap>", line 2254, in _gcd_import
  File "<frozen importlib._bootstrap>", line 2237, in _find_and_load
  File "<frozen importlib._bootstrap>", line 2226, in _find_and_load_unlocked
  File "<frozen importlib._bootstrap>", line 1200, in _load_unlocked
  File "<frozen importlib._bootstrap>", line 1129, in _exec
  File "<frozen importlib._bootstrap>", line 1471, in exec_module
  File "<frozen importlib._bootstrap>", line 321, in _call_with_frames_removed
  File "/Users/jiho/Documents/workspace/django/cheez/cheez/cheez/urls.py", line 7, in <module>
    from webpage import views as webpage_views
  File "/Users/jiho/Documents/workspace/django/cheez/cheez/webpage/views.py", line 8, in <module>
    @permission_required()
TypeError: permission_required() missing 1 required positional argument: 'perm'
Internal Server Error: /530
Traceback (most recent call last):
  File "/Users/jiho/Documents/workspace/django/cheez/venv/lib/python3.4/site-packages/django/template/base.py", line 337, in parse
    compile_func = self.tags[command]
KeyError: 'static'

During handling of the above exception, another exception occurred:

Traceback (most recent call last):
  File "/Users/jiho/Documents/workspace/django/cheez/venv/lib/python3.4/site-packages/django/core/handlers/base.py", line 132, in get_response
    response = wrapped_callback(request, *callback_args, **callback_kwargs)
  File "/Users/jiho/Documents/workspace/django/cheez/cheez/webpage/views.py", line 18, in share_view
    'post': post
  File "/Users/jiho/Documents/workspace/django/cheez/venv/lib/python3.4/site-packages/django/shortcuts.py", line 67, in render
    template_name, context, request=request, using=using)
  File "/Users/jiho/Documents/workspace/django/cheez/venv/lib/python3.4/site-packages/django/template/loader.py", line 98, in render_to_string
    template = get_template(template_name, using=using)
  File "/Users/jiho/Documents/workspace/django/cheez/venv/lib/python3.4/site-packages/django/template/loader.py", line 35, in get_template
    return engine.get_template(template_name, dirs)
  File "/Users/jiho/Documents/workspace/django/cheez/venv/lib/python3.4/site-packages/django/template/backends/django.py", line 30, in get_template
    return Template(self.engine.get_template(template_name, dirs))
  File "/Users/jiho/Documents/workspace/django/cheez/venv/lib/python3.4/site-packages/django/template/engine.py", line 167, in get_template
    template, origin = self.find_template(template_name, dirs)
  File "/Users/jiho/Documents/workspace/django/cheez/venv/lib/python3.4/site-packages/django/template/engine.py", line 141, in find_template
    source, display_name = loader(name, dirs)
  File "/Users/jiho/Documents/workspace/django/cheez/venv/lib/python3.4/site-packages/django/template/loaders/base.py", line 13, in __call__
    return self.load_template(template_name, template_dirs)
  File "/Users/jiho/Documents/workspace/django/cheez/venv/lib/python3.4/site-packages/django/template/loaders/base.py", line 23, in load_template
    template = Template(source, origin, template_name, self.engine)
  File "/Users/jiho/Documents/workspace/django/cheez/venv/lib/python3.4/site-packages/django/template/base.py", line 190, in __init__
    self.nodelist = engine.compile_string(template_string, origin)
  File "/Users/jiho/Documents/workspace/django/cheez/venv/lib/python3.4/site-packages/django/template/engine.py", line 261, in compile_string
    return parser.parse()
  File "/Users/jiho/Documents/workspace/django/cheez/venv/lib/python3.4/site-packages/django/template/base.py", line 339, in parse
    self.invalid_block_tag(token, command, parse_until)
  File "/Users/jiho/Documents/workspace/django/cheez/venv/lib/python3.4/site-packages/django/template/base.py", line 395, in invalid_block_tag
    raise self.error(token, "Invalid block tag: '%s'" % command)
django.template.base.TemplateSyntaxError: Invalid block tag: 'static'
Invalid HTTP_HOST header: 'localhost:8000'. You may need to add 'localhost' to ALLOWED_HOSTS.
Invalid HTTP_HOST header: 'localhost:8000'. You may need to add 'localhost' to ALLOWED_HOSTS.
Invalid HTTP_HOST header: 'localhost:8000'. You may need to add 'localhost' to ALLOWED_HOSTS.
Invalid HTTP_HOST header: 'localhost:8000'. You may need to add 'localhost' to ALLOWED_HOSTS.
Invalid HTTP_HOST header: 'localhost:8000'. You may need to add 'localhost' to ALLOWED_HOSTS.
